[2023-05-04T10:36:42.854+0000] {taskinstance.py:1125} INFO - Dependencies all met for dep_context=non-requeueable deps ti=<TaskInstance: our_first_dag_v2.second_task scheduled__2021-08-02T00:00:00+00:00 [queued]>
[2023-05-04T10:36:43.042+0000] {taskinstance.py:1125} INFO - Dependencies all met for dep_context=requeueable deps ti=<TaskInstance: our_first_dag_v2.second_task scheduled__2021-08-02T00:00:00+00:00 [queued]>
[2023-05-04T10:36:43.046+0000] {taskinstance.py:1331} INFO - Starting attempt 1 of 6
[2023-05-04T10:36:43.398+0000] {taskinstance.py:1350} INFO - Executing <Task(BashOperator): second_task> on 2021-08-02 00:00:00+00:00
[2023-05-04T10:36:43.478+0000] {standard_task_runner.py:57} INFO - Started process 1610 to run task
[2023-05-04T10:36:43.544+0000] {standard_task_runner.py:84} INFO - Running: ['***', 'tasks', 'run', 'our_first_dag_v2', 'second_task', 'scheduled__2021-08-02T00:00:00+00:00', '--job-id', '388', '--raw', '--subdir', 'DAGS_FOLDER/our_fist_dag.py', '--cfg-path', '/tmp/tmpm_azgj80']
[2023-05-04T10:36:43.610+0000] {standard_task_runner.py:85} INFO - Job 388: Subtask second_task
[2023-05-04T10:36:46.051+0000] {task_command.py:410} INFO - Running <TaskInstance: our_first_dag_v2.second_task scheduled__2021-08-02T00:00:00+00:00 [running]> on host a2c266875370
[2023-05-04T10:36:50.607+0000] {taskinstance.py:1570} INFO - Exporting env vars: AIRFLOW_CTX_DAG_OWNER='jose-holgado' AIRFLOW_CTX_DAG_ID='our_first_dag_v2' AIRFLOW_CTX_TASK_ID='second_task' AIRFLOW_CTX_EXECUTION_DATE='2021-08-02T00:00:00+00:00' AIRFLOW_CTX_TRY_NUMBER='1' AIRFLOW_CTX_DAG_RUN_ID='scheduled__2021-08-02T00:00:00+00:00'
[2023-05-04T10:36:50.626+0000] {subprocess.py:63} INFO - Tmp dir root location: 
 /tmp
[2023-05-04T10:36:50.628+0000] {subprocess.py:75} INFO - Running command: ['/bin/bash', '-c', "echo I'm the task2 and will be running after task 1"]
[2023-05-04T10:36:50.728+0000] {subprocess.py:86} INFO - Output:
[2023-05-04T10:36:50.730+0000] {subprocess.py:93} INFO - /bin/bash: -c: line 1: unexpected EOF while looking for matching `''
[2023-05-04T10:36:50.731+0000] {subprocess.py:93} INFO - /bin/bash: -c: line 2: syntax error: unexpected end of file
[2023-05-04T10:36:50.733+0000] {subprocess.py:97} INFO - Command exited with return code 2
[2023-05-04T10:36:50.930+0000] {taskinstance.py:1847} ERROR - Task failed with exception
Traceback (most recent call last):
  File "/home/airflow/.local/lib/python3.7/site-packages/airflow/operators/bash.py", line 211, in execute
    f"Bash command failed. The command returned a non-zero exit code {result.exit_code}."
airflow.exceptions.AirflowException: Bash command failed. The command returned a non-zero exit code 2.
[2023-05-04T10:36:50.980+0000] {taskinstance.py:1373} INFO - Marking task as UP_FOR_RETRY. dag_id=our_first_dag_v2, task_id=second_task, execution_date=20210802T000000, start_date=20230504T103642, end_date=20230504T103650
[2023-05-04T10:36:51.108+0000] {standard_task_runner.py:109} ERROR - Failed to execute job 388 for task second_task (Bash command failed. The command returned a non-zero exit code 2.; 1610)
[2023-05-04T10:36:51.268+0000] {local_task_job_runner.py:232} INFO - Task exited with return code 1
[2023-05-04T10:36:52.521+0000] {taskinstance.py:2674} INFO - 0 downstream tasks scheduled from follow-on schedule check
