[2023-05-04T11:03:27.688+0000] {taskinstance.py:1125} INFO - Dependencies all met for dep_context=non-requeueable deps ti=<TaskInstance: our_dag_with_python_operator_v04.greet scheduled__2023-05-03T00:00:00+00:00 [queued]>
[2023-05-04T11:03:27.694+0000] {taskinstance.py:1125} INFO - Dependencies all met for dep_context=requeueable deps ti=<TaskInstance: our_dag_with_python_operator_v04.greet scheduled__2023-05-03T00:00:00+00:00 [queued]>
[2023-05-04T11:03:27.694+0000] {taskinstance.py:1331} INFO - Starting attempt 1 of 6
[2023-05-04T11:03:27.702+0000] {taskinstance.py:1350} INFO - Executing <Task(PythonOperator): greet> on 2023-05-03 00:00:00+00:00
[2023-05-04T11:03:27.706+0000] {standard_task_runner.py:57} INFO - Started process 518 to run task
[2023-05-04T11:03:27.709+0000] {standard_task_runner.py:84} INFO - Running: ['***', 'tasks', 'run', 'our_dag_with_python_operator_v04', 'greet', 'scheduled__2023-05-03T00:00:00+00:00', '--job-id', '998', '--raw', '--subdir', 'DAGS_FOLDER/create_dag_with_python.py', '--cfg-path', '/tmp/tmpx345dbkm']
[2023-05-04T11:03:27.712+0000] {standard_task_runner.py:85} INFO - Job 998: Subtask greet
[2023-05-04T11:03:27.779+0000] {task_command.py:410} INFO - Running <TaskInstance: our_dag_with_python_operator_v04.greet scheduled__2023-05-03T00:00:00+00:00 [running]> on host 4ea71e7281fb
[2023-05-04T11:03:27.846+0000] {taskinstance.py:1570} INFO - Exporting env vars: AIRFLOW_CTX_DAG_OWNER='jose-holgado' AIRFLOW_CTX_DAG_ID='our_dag_with_python_operator_v04' AIRFLOW_CTX_TASK_ID='greet' AIRFLOW_CTX_EXECUTION_DATE='2023-05-03T00:00:00+00:00' AIRFLOW_CTX_TRY_NUMBER='1' AIRFLOW_CTX_DAG_RUN_ID='scheduled__2023-05-03T00:00:00+00:00'
[2023-05-04T11:03:27.848+0000] {taskinstance.py:1847} ERROR - Task failed with exception
Traceback (most recent call last):
  File "/home/airflow/.local/lib/python3.7/site-packages/airflow/operators/python.py", line 181, in execute
    return_value = self.execute_callable()
  File "/home/airflow/.local/lib/python3.7/site-packages/airflow/operators/python.py", line 198, in execute_callable
    return self.python_callable(*self.op_args, **self.op_kwargs)
  File "/opt/airflow/dags/create_dag_with_python.py", line 15, in greet
    name = ti.xcoms_pull(task_ids='get_name')
AttributeError: 'TaskInstance' object has no attribute 'xcoms_pull'
[2023-05-04T11:03:27.860+0000] {taskinstance.py:1373} INFO - Marking task as UP_FOR_RETRY. dag_id=our_dag_with_python_operator_v04, task_id=greet, execution_date=20230503T000000, start_date=20230504T110327, end_date=20230504T110327
[2023-05-04T11:03:27.875+0000] {standard_task_runner.py:109} ERROR - Failed to execute job 998 for task greet ('TaskInstance' object has no attribute 'xcoms_pull'; 518)
[2023-05-04T11:03:27.932+0000] {local_task_job_runner.py:232} INFO - Task exited with return code 1
[2023-05-04T11:03:27.951+0000] {taskinstance.py:2674} INFO - 0 downstream tasks scheduled from follow-on schedule check
