[2023-05-04T10:36:55.831+0000] {taskinstance.py:1125} INFO - Dependencies all met for dep_context=non-requeueable deps ti=<TaskInstance: our_first_dag_v2.second_task scheduled__2021-08-08T00:00:00+00:00 [queued]>
[2023-05-04T10:36:55.929+0000] {taskinstance.py:1125} INFO - Dependencies all met for dep_context=requeueable deps ti=<TaskInstance: our_first_dag_v2.second_task scheduled__2021-08-08T00:00:00+00:00 [queued]>
[2023-05-04T10:36:55.935+0000] {taskinstance.py:1331} INFO - Starting attempt 1 of 6
[2023-05-04T10:36:56.629+0000] {taskinstance.py:1350} INFO - Executing <Task(BashOperator): second_task> on 2021-08-08 00:00:00+00:00
[2023-05-04T10:36:56.637+0000] {standard_task_runner.py:57} INFO - Started process 1649 to run task
[2023-05-04T10:36:56.661+0000] {standard_task_runner.py:84} INFO - Running: ['***', 'tasks', 'run', 'our_first_dag_v2', 'second_task', 'scheduled__2021-08-08T00:00:00+00:00', '--job-id', '401', '--raw', '--subdir', 'DAGS_FOLDER/our_fist_dag.py', '--cfg-path', '/tmp/tmprn24qe1p']
[2023-05-04T10:36:56.687+0000] {standard_task_runner.py:85} INFO - Job 401: Subtask second_task
[2023-05-04T10:36:56.855+0000] {task_command.py:410} INFO - Running <TaskInstance: our_first_dag_v2.second_task scheduled__2021-08-08T00:00:00+00:00 [running]> on host a2c266875370
[2023-05-04T10:36:57.070+0000] {taskinstance.py:1570} INFO - Exporting env vars: AIRFLOW_CTX_DAG_OWNER='jose-holgado' AIRFLOW_CTX_DAG_ID='our_first_dag_v2' AIRFLOW_CTX_TASK_ID='second_task' AIRFLOW_CTX_EXECUTION_DATE='2021-08-08T00:00:00+00:00' AIRFLOW_CTX_TRY_NUMBER='1' AIRFLOW_CTX_DAG_RUN_ID='scheduled__2021-08-08T00:00:00+00:00'
[2023-05-04T10:36:57.072+0000] {subprocess.py:63} INFO - Tmp dir root location: 
 /tmp
[2023-05-04T10:36:57.073+0000] {subprocess.py:75} INFO - Running command: ['/bin/bash', '-c', "echo I'm the task2 and will be running after task 1"]
[2023-05-04T10:36:57.092+0000] {subprocess.py:86} INFO - Output:
[2023-05-04T10:36:57.103+0000] {subprocess.py:93} INFO - /bin/bash: -c: line 1: unexpected EOF while looking for matching `''
[2023-05-04T10:36:57.104+0000] {subprocess.py:93} INFO - /bin/bash: -c: line 2: syntax error: unexpected end of file
[2023-05-04T10:36:57.105+0000] {subprocess.py:97} INFO - Command exited with return code 2
[2023-05-04T10:36:57.123+0000] {taskinstance.py:1847} ERROR - Task failed with exception
Traceback (most recent call last):
  File "/home/airflow/.local/lib/python3.7/site-packages/airflow/operators/bash.py", line 211, in execute
    f"Bash command failed. The command returned a non-zero exit code {result.exit_code}."
airflow.exceptions.AirflowException: Bash command failed. The command returned a non-zero exit code 2.
[2023-05-04T10:36:57.139+0000] {taskinstance.py:1373} INFO - Marking task as UP_FOR_RETRY. dag_id=our_first_dag_v2, task_id=second_task, execution_date=20210808T000000, start_date=20230504T103655, end_date=20230504T103657
[2023-05-04T10:36:57.163+0000] {standard_task_runner.py:109} ERROR - Failed to execute job 401 for task second_task (Bash command failed. The command returned a non-zero exit code 2.; 1649)
[2023-05-04T10:36:57.223+0000] {local_task_job_runner.py:232} INFO - Task exited with return code 1
[2023-05-04T10:36:57.247+0000] {taskinstance.py:2674} INFO - 0 downstream tasks scheduled from follow-on schedule check
