[2023-05-04T10:36:53.324+0000] {taskinstance.py:1125} INFO - Dependencies all met for dep_context=non-requeueable deps ti=<TaskInstance: our_first_dag_v2.second_task scheduled__2021-08-07T00:00:00+00:00 [queued]>
[2023-05-04T10:36:53.444+0000] {taskinstance.py:1125} INFO - Dependencies all met for dep_context=requeueable deps ti=<TaskInstance: our_first_dag_v2.second_task scheduled__2021-08-07T00:00:00+00:00 [queued]>
[2023-05-04T10:36:53.461+0000] {taskinstance.py:1331} INFO - Starting attempt 1 of 6
[2023-05-04T10:36:54.211+0000] {taskinstance.py:1350} INFO - Executing <Task(BashOperator): second_task> on 2021-08-07 00:00:00+00:00
[2023-05-04T10:36:54.237+0000] {standard_task_runner.py:57} INFO - Started process 1637 to run task
[2023-05-04T10:36:54.260+0000] {standard_task_runner.py:84} INFO - Running: ['***', 'tasks', 'run', 'our_first_dag_v2', 'second_task', 'scheduled__2021-08-07T00:00:00+00:00', '--job-id', '396', '--raw', '--subdir', 'DAGS_FOLDER/our_fist_dag.py', '--cfg-path', '/tmp/tmphpr90i58']
[2023-05-04T10:36:54.284+0000] {standard_task_runner.py:85} INFO - Job 396: Subtask second_task
[2023-05-04T10:36:54.774+0000] {task_command.py:410} INFO - Running <TaskInstance: our_first_dag_v2.second_task scheduled__2021-08-07T00:00:00+00:00 [running]> on host a2c266875370
[2023-05-04T10:36:55.415+0000] {taskinstance.py:1570} INFO - Exporting env vars: AIRFLOW_CTX_DAG_OWNER='jose-holgado' AIRFLOW_CTX_DAG_ID='our_first_dag_v2' AIRFLOW_CTX_TASK_ID='second_task' AIRFLOW_CTX_EXECUTION_DATE='2021-08-07T00:00:00+00:00' AIRFLOW_CTX_TRY_NUMBER='1' AIRFLOW_CTX_DAG_RUN_ID='scheduled__2021-08-07T00:00:00+00:00'
[2023-05-04T10:36:55.418+0000] {subprocess.py:63} INFO - Tmp dir root location: 
 /tmp
[2023-05-04T10:36:55.421+0000] {subprocess.py:75} INFO - Running command: ['/bin/bash', '-c', "echo I'm the task2 and will be running after task 1"]
[2023-05-04T10:36:55.472+0000] {subprocess.py:86} INFO - Output:
[2023-05-04T10:36:55.490+0000] {subprocess.py:93} INFO - /bin/bash: -c: line 1: unexpected EOF while looking for matching `''
[2023-05-04T10:36:55.491+0000] {subprocess.py:93} INFO - /bin/bash: -c: line 2: syntax error: unexpected end of file
[2023-05-04T10:36:55.498+0000] {subprocess.py:97} INFO - Command exited with return code 2
[2023-05-04T10:36:55.524+0000] {taskinstance.py:1847} ERROR - Task failed with exception
Traceback (most recent call last):
  File "/home/airflow/.local/lib/python3.7/site-packages/airflow/operators/bash.py", line 211, in execute
    f"Bash command failed. The command returned a non-zero exit code {result.exit_code}."
airflow.exceptions.AirflowException: Bash command failed. The command returned a non-zero exit code 2.
[2023-05-04T10:36:55.537+0000] {taskinstance.py:1373} INFO - Marking task as UP_FOR_RETRY. dag_id=our_first_dag_v2, task_id=second_task, execution_date=20210807T000000, start_date=20230504T103653, end_date=20230504T103655
[2023-05-04T10:36:55.582+0000] {standard_task_runner.py:109} ERROR - Failed to execute job 396 for task second_task (Bash command failed. The command returned a non-zero exit code 2.; 1637)
[2023-05-04T10:36:55.661+0000] {local_task_job_runner.py:232} INFO - Task exited with return code 1
[2023-05-04T10:36:55.765+0000] {taskinstance.py:2674} INFO - 0 downstream tasks scheduled from follow-on schedule check
